Workbook

Sheet Intro
B7: GHG Emission Inventory and Carbon Footprint of MSC Complex
E9: GHG Atlas MSC | K9: File Name:
E10: 2.2 | K10: Version:
E11: MSC | K11: Owner:
H12: Behineh Sazan Sanat Tasisat | J12: Shayan Seif | K12: Developer:
E13: 2025 August | K13: Date:
B14: This electronic file is developed to facilitate data management and reporting for MSC Complex GHG Inventory (Section 1) and Carbon Footprint of Products (Section 2).
B18: 1. Data shall be complete and accurate to ensure the accountability of the results.
B21: 2. Units of all input data shall be checked with the required measurement system.
B24: 3. Section 1 contains all MSC areas for GHG Inventory based on ISO 14064-1:2018.
B27: 4. Section 2 contains all MSC products for Carbon Footprinting based on ISO 14067:2018.
J30: 5. Legends of cells:
D31: Cells that has to be filled by user
D32: Cells that can be modified by user
D33: Cells that reports the results of calculations
D34: Notes and guidance
J35: 6. User information:
B37: Date of completion: | E37: User Name: | H37: Title: | K37: Contact information:
B39: 7. Notes: User can add notes here.

Sheet Unit List
B7: List of Unit Processes and Cost Centers
B8: Cost Center Code | C8: Cost Center | D8: Unit Process | E8: Area | F8: Area Code
B9: 1107 | C9: Raw Material Maintenance | D9: - | E9: Iron Making | F9: 1
B10: 1110 | C10: Iron Ore and Pellet Yard | D10: Yard | E10: Iron Making | F10: 1
B11: 1120 | C11: Limestone Calcination Plant | D11: Lime Making | E11: Iron Making | F11: 1
B12: 1130 | C12: Lime Hydration Plant | D12: Lime Hydration | E12: Iron Making | F12: 1
B13: 1140 | C13: Dolomite Plant | D13: Dolomite Making | E13: Iron Making | F13: 1
B14: 1207 | C14: Pelletizing Maintenance | D14: - | E14: Iron Making | F14: 1
B15: 1210 | C15: Pelletizing Plant | D15: Pelletizing | E15: Iron Making | F15: 1
B16: 1307 | C16: Direct Reduction 1 Maintenance | D16: - | E16: Iron Making | F16: 1
B17: 1310 | C17: Direct Reduction 1 | D17: Direct Reduction | E17: Iron Making | F17: 1
B18: 1315 | C18: Direct Reduction 2 | D18: Direct Reduction | E18: Iron Making | F18: 1
B19: 1317 | C19: Direct Reduction 2 Maintenance | D19: - | E19: Iron Making | F19: 1
B20: 1320 | C20: Material Handling of Direct Reduction 1 | D20: Direct Reduction | E20: Iron Making | F20: 1
... B241: 9950 | C241: Mining Affairs | D241: - | E241: TAS | F241: 9

Sheet Settings
B7: Year
B8: 1403 | C8: 2024
B11: Parameters
B12: Parameters | D12: Value | E12: Farsi Description | G12: Source
B13: Working hours (hrs/yr) | D13: 8760 | E13: تعداد ساعت کاری در سال (hrs/yr) | G13: MSC
B14: Working days for Shift Employees | D14: 365 | E14: تعداد روزهای کاری پرسنل شیفت در سال | G14: MSC
B15: Working days for Day Employees | D15: 250 | E15: تعداد روزهای کاری پرسنل روز کار در سال | G15: MSC
B16: Methane weight percent in natural gas | D16: 0.9028 | E16: درصد وزنی متان در گاز طبیعی | G16: 1
B17: Dollar to Rial exchange rate | D17: 373005 | E17: نرخ برابری دلار به ریال (متوسط نرخ موزون) | G17: 2
G18: Source 1: Chemical composition of natural gas delivered to MSC.
G19: Source 2: https://cbi.ir/simplelist/30450.aspx
B22: GWPs
B23: CO2 | C23: CH4 (C,B) | D23: N2O | E23: SF6 | F23: CFC-12 | G23: CH4 (F,V)
B24: 1 | C24: 27 | D24: 273 | E24: 24300 | F24: 12500 | G24: 29.8
G25: Source: IPCC Sixth Assessment Report (AR6).
B28: LHV of fuels
B29: Fuel type | C29: LHV | D29: Unit | E29: Source | F29: Unit | G29: Notes
B30: Natural Gas | C30: 15 | D30: GJ/kNm3 | E30: 1 | F30: kNm3
B31: Gas oil | C31: 0.01 | D31: GJ/Lit | E31: 2 | F31: Lit
B32: Methane | C32: 5 | D32: GJ/ton | E32: 3 | F32: ton
B33: Butane | C33: 4 | D33: GJ/ton | E33: 3 | F33: ton
B34: Acetylene | C34: 5 | D34: GJ/ton | E34: 3 | F34: ton
B35: Oil | C35: 0.0357 | D35: GJ/Lit | E35: 2 | F35: Lit
B36: Others | D36: GJ/SCM
F37: Source 1: Calculation based on chemical composition of natural gas delivered to MSC.
B38: Source 2: API Compendium of Greenhouse Gas Emissions Methodologies for the Oil and Natural Gas Industry, 2009.
F40: Source 3: https://www.engineeringtoolbox.com/fuels-higher-calorific-values-d_169.html
B43: EFs: Fuel Combustion
B44: Fuel type | C44: EF- (t/GJ) | F44: Source
C45: CO2 | D45: CH4 | E45: N2O
B46: Natural Gas | C46: 0.0561 | D46: 1e-06 | E46: 1e-07 | F46: 1
B47: Gas oil | C47: 0.0741 | D47: 3e-06 | E47: 6e-07 | F47: 1
B48: Methane | C48: 7 | D48: 1e-06 | E48: 1e-07 | F48: 4
B49: Butane | C49: 6 | D49: 2.8e-06 | E49: 5.6e-07 | F49: 3
B50: Acetylene | C50: 6 | D50: 0 | E50: 0 | F50: 2
B51: Oil | C51: 7 | D51: 3e-06 | E51: 6e-07 | F51: 1
B52: Others
F53: Source 1: 2006 IPCC Guidelines for National Greenhouse Gas Inventories.
F54: Source 2: Methodology for reporting B.C. public sector greenhouse gas emissions, 2011.
F55: Source 3: Emission Factors for Greenhouse Gas Inventories, 2014.
...

Sheet Data Quality
B7: Data Quality Sheet | I7: Data Quality Assessment | N7: Uncertainty Assessment
B8: Section | C8: Sheet Name | D8: Parameters | E8: Type of Data | G8: Notes/References | H8: Documents of MSC | I8: Technology | J8: Time | K8: Geography | L8: Completeness | M8: Reliability | N8: Type of Uncertainty | O8: Uncertainty Rank
E9: Primary Data | F9: Secondary Data
B10: Section 1: Emission Inventory | C10: Combustion | D10: Annual fuel consumption | G10: Site-specific | H10: Cost Center Documents. | N10: Parameter
D11: LHV of fuels | G11: Site-specific | H11: Chemical Composition of NG. | N11: Model
D12: Emission factors | G12: Refer to Setting Sheet to access references | N12: Parameter
C13: Vent | D13: Annual production | G13: Site-specific | H13: Cost Center Documents. | N13: Parameter
D14: Emission factors | G14: Refer to Setting Sheet to access references | N14: Parameter
C15: Fugitive | D15: Annual consumption | G15: Site-specific | H15: Cost Center Documents. | N15: Parameter
D16: Equipment count | G16: Site-specific | H16: P&IDs of facilities. | N16: Parameter
D17: Emission factors | G17: Refer to Setting Sheet to access references | N17: Parameter
D18: Control efficiency | G18: Site-specific | H18: Personnel interview. | N18: Scenario
C19: Electricity | D19: Electricity consumption | G19: Site-specific | H19: Cost Center Documents. | N19: Parameter
D20: Emission factors | G20: Refer to Setting Sheet to access references | N20: Parameter
D21: Distribution loss | G21: Refer to Setting Sheet to access references | N21: Parameter
C22: On-Site Tran. | D22: Annual fuel consumption | G22: Site-specific | H22: Cost Center Documents. | N22: Parameter
D23: Emission factors | G23: Refer to Setting Sheet to access references | N23: Parameter
C24: Upstream Tran. | D24: Origin | G24: Site-specific | H24: Transportation Reports. | N24: Parameter
D25: Distance | G25: Refer to Setting Sheet to access references | N25: Parameter
D26: Weight | G26: Site-specific | H26: Transportation Reports. | N26: Parameter
D27: Emission factors | G27: Refer to Setting Sheet to access references | N27: Parameter
C28: Downstream Tran. | D28: Destination | G28: Site-specific | H28: Transportation Reports. | N28: Parameter
D29: Distance | G29: Refer to Setting Sheet to access references | N29: Parameter
D30: Weight | G30: Site-specific | H30: Transportation Reports. | N30: Parameter
D31: Emission factors | G31: Refer to Setting Sheet to access references | N31: Parameter
C32: Employee Commuting | D32: Annual distance traveled | G32: Site-specific | H32: Transportation Reports. | N32: Parameter
D33: Emission factors | G33: Refer to Setting Sheet to access references | N33: Parameter
D34: Personnel count | G34: Site-specific | H34: Transportation Reports. | N34: Parameter
C35: Business Travel | D35: Annual distance traveled | G35: Site-specific | H35: Transportation Reports. | N35: Parameter
D36: Emission factors | G36: Refer to Setting Sheet to access references | N36: Parameter
D37: Travel counts | G37: Site-specific | H37: Transportation Reports. | N37: Parameter
C38: Purchased Material | D38: Annual consumption | G38: Site-specific | H38: Cost Center Documents. | N38: Parameter
D39: Emission factors | G39: Refer to Setting Sheet to access references | N39: Parameter
C40: Ancillary Input | D40: Annual consumption | G40: Site-specific | H40: Cost Center Documents. | N40: Parameter
D41: Emission factors | G41: Refer to Setting Sheet to access references | N41: Parameter
C42: Purchased Services | D42: Annual consumption | G42: Site-specific | H42: Cost Center Documents. | N42: Parameter
D43: Emission factors | G43: Refer to Setting Sheet to access references | N43: Parameter
C44: Waste | D44: Annual production | G44: Site-specific | H44: Waste Management Reports. | N44: Parameter
D45: Management approach | G45: Site-specific | H45: Personnel interview. | N45: Scenario
D46: Emission factors | G46: Refer to Setting Sheet to access references | N46: Parameter
...

Sheet Sensitivity
B7: Sensitivity Analysis
B8: Parameters with high uncertainty | C8: Selected case in the study | D8: Scenario | E8: Description | F8: Total GHG Emissions (tCO2e) | G8: Variation of Total Emissions | H8: Carbon Footprint of "Slab" (tCO2e/t) | I8: Variation of CFP | J8: Remarks
D9: Final | E9: The present conditions of study | F9: ='Tables & Graphs'!E30 -> 20162467 | H9: ='Units CF'!E105 -> 2.3301682

Sheet Inventory
B7: GHG Emission Inventory
B8: No. | C8: Area | D8: Area Code | E8: Emission Source | F8: Category | G8: Sign | H8: Category No. | I8: Scope | J8: Emission Code | K8: CO2 (tCO2/y) | L8: CH4 (tCH4/y) | M8: N2O (tN2O/y) | N8: SF6 (tSF6/y) | O8: Emission (tCO2e/y) | P8: Emission Share (%)
B9: 1 | C9: Iron Making | D9: =VLOOKUP(C9,Settings!$B$341:C364,2,FALSE) -> 1 | E9: Fossil Fuel Combustion | F9: Combustion | G9: =VLOOKUP(F9,Settings!$B$163:D186,3,FALSE) -> C | H9: =VLOOKUP(F9,Settings!$B$163:D186,2,FALSE) -> 1 | I9: =VLOOKUP(F9,Settings!$B$163:F180,5,FALSE) -> 1 | J9: =_xlfn.TEXTJOIN("-",,D9,G9,B9) -> 1-C-1 | K9: =VLOOKUP(J9,Combustion!$J$103:$P$110,4,FALSE) -> 126420.9 | L9: =VLOOKUP(J9,Combustion!$J$103:$P$110,5,FALSE) -> 2.2524975 | M9: =VLOOKUP(J9,Combustion!$J$103:$P$110,6,FALSE) -> 0.22525242 | N9: 0 | O9: =VLOOKUP(J9,Combustion!$J$103:$P$110,7,FALSE) -> 126543.21 | P9: =O9/$O$195 -> 0.0062761768
B10: 2 | C10: Steel Making | D10: =VLOOKUP(C10,Settings!$B$341:C371,2,FALSE) -> 2 | E10: Fossil Fuel Combustion | F10: Combustion | G10: =VLOOKUP(F10,Settings!$B$163:D195,3,FALSE) -> C | H10: =VLOOKUP(F10,Settings!$B$163:D195,2,FALSE) -> 1 | I10: =VLOOKUP(F10,Settings!$B$163:F180,5,FALSE) -> 1 | J10: =_xlfn.TEXTJOIN("-",,D10,G10,B10) -> 2-C-2 | K10: =VLOOKUP(J10,Combustion!$J$103:$P$110,4,FALSE) -> 34851.215 | L10: =VLOOKUP(J10,Combustion!$J$103:$P$110,5,FALSE) -> 0.61872455 | M10: =VLOOKUP(J10,Combustion!$J$103:$P$110,6,FALSE) -> 0.061879201 | N10: 0 | O10: =VLOOKUP(J10,Combustion!$J$103:$P$110,7,FALSE) -> 34884.813 | P10: =O10/$O$195 -> 0.0017301858
B11: 3 | C11: Hot Rolling | D11: =VLOOKUP(C11,Settings!$B$341:C384,2,FALSE) -> 3 | E11: Fossil Fuel Combustion | F11: Combustion | G11: =VLOOKUP(F11,Settings!$B$163:D202,3,FALSE) -> C | H11: =VLOOKUP(F11,Settings!$B$163:D201,2,FALSE) -> 1 | I11: =VLOOKUP(F11,Settings!$B$163:F181,5,FALSE) -> 1 | J11: =_xlfn.TEXTJOIN("-",,D11,G11,B11) -> 3-C-3 | K11: =VLOOKUP(J11,Combustion!$J$103:$P$110,4,FALSE) -> 175384.09 | L11: =VLOOKUP(J11,Combustion!$J$103:$P$110,5,FALSE) -> 3.125112 | M11: =VLOOKUP(J11,Combustion!$J$103:$P$110,6,FALSE) -> 0.31251433 | N11: 0 | O11: =VLOOKUP(J11,Combustion!$J$103:$P$110,7,FALSE) -> 175553.78 | P11: =O11/$O$195 -> 0.0087069594
B12: 4 | C12: Cold Rolling | D12: =VLOOKUP(C12,Settings!$B$341:C428,2,FALSE) -> 4 | E12: Fossil Fuel Combustion | F12: Combustion | G12: =VLOOKUP(F12,Settings!$B$163:D377,3,FALSE) -> C | H12: =VLOOKUP(F12,Settings!$B$163:D376,2,FALSE) -> 1 | I12: =VLOOKUP(F12,Settings!$B$163:F213,5,FALSE) -> 1 | J12: =_xlfn.TEXTJOIN("-",,D12,G12,B12) -> 4-C-4 | K12: =VLOOKUP(J12,Combustion!$J$103:$P$110,4,FALSE) -> 27783.999 | L12: =VLOOKUP(J12,Combustion!$J$103:$P$110,5,FALSE) -> 0.4891918 | M12: =VLOOKUP(J12,Combustion!$J$103:$P$110,6,FALSE) -> 0.04893549 | N12: 0 | O12: =VLOOKUP(J12,Combustion!$J$103:$P$110,7,FALSE) -> 27810.566 | P12: =O12/$O$195 -> 0.0013793236
B13: 5 | C13: Utility | D13: =VLOOKUP(C13,Settings!$B$341:C461,2,FALSE) -> 5 | E13: Fossil Fuel Combustion | F13: Combustion | G13: =VLOOKUP(F13,Settings!$B$163:D395,3,FALSE) -> C | H13: =VLOOKUP(F13,Settings!$B$163:D395,2,FALSE) -> 1 | I13: =VLOOKUP(F13,Settings!$B$163:F214,5,FALSE) -> 1 | J13: =_xlfn.TEXTJOIN("-",,D13,G13,B13) -> 5-C-5 | K13: =VLOOKUP(J13,Combustion!$J$103:$P$110,4,FALSE) -> 827049.63 | L13: =VLOOKUP(J13,Combustion!$J$103:$P$110,5,FALSE) -> 14.948705 | M13: =VLOOKUP(J13,Combustion!$J$103:$P$110,6,FALSE) -> 1.5317712 | N13: 0 | O13: =VLOOKUP(J13,Combustion!$J$103:$P$110,7,FALSE) -> 827871.42 | P13: =O13/$O$195 -> 0.041060026
B14: 6 | C14: Transportation | D14: =VLOOKUP(C14,Settings!$B$341:C503,2,FALSE) -> 6 | E14: Fossil Fuel Combustion | F14: Combustion | G14: =VLOOKUP(F14,Settings!$B$163:D425,3,FALSE) -> C | H14: =VLOOKUP(F14,Settings!$B$163:D424,2,FALSE) -> 1 | I14: =VLOOKUP(F14,Settings!$B$163:F215,5,FALSE) -> 1 | J14: =_xlfn.TEXTJOIN("-",,D14,G14,B14) -> 6-C-6 | K14: =VLOOKUP(J14,Combustion!$J$103:$P$110,4,FALSE) -> 2.376 | L14: =VLOOKUP(J14,Combustion!$J$103:$P$110,5,FALSE) -> 1.1088e-06 | M14: =VLOOKUP(J14,Combustion!$J$103:$P$110,6,FALSE) -> 2.2176e-07 | N14: 0 | O14: =VLOOKUP(J14,Combustion!$J$103:$P$110,7,FALSE) -> 2.3760905 | P14: =O14/$O$195 -> 1.1784721e-07
B15: 7 | C15: Maintenance | D15: =VLOOKUP(C15,Settings!$B$341:C521,2,FALSE) -> 7 | E15: Fossil Fuel Combustion | F15: Combustion | G15: =VLOOKUP(F15,Settings!$B$163:D443,3,FALSE) -> C | H15: =VLOOKUP(F15,Settings!$B$163:D442,2,FALSE) -> 1 | I15: =VLOOKUP(F15,Settings!$B$163:F216,5,FALSE) -> 1 | J15: =_xlfn.TEXTJOIN("-",,D15,G15,B15) -> 7-C-7 | K15: =VLOOKUP(J15,Combustion!$J$103:$P$110,4,FALSE) -> 13894.644 | L15: =VLOOKUP(J15,Combustion!$J$103:$P$110,5,FALSE) -> 0.24738219 | M15: =VLOOKUP(J15,Combustion!$J$103:$P$110,6,FALSE) -> 0.024738994 | N15: 0 | O15: =VLOOKUP(J15,Combustion!$J$103:$P$110,7,FALSE) -> 13908.077 | P15: =O15/$O$195 -> 0.00068980036
B16: 8 | C16: TAS | D16: =VLOOKUP(C16,Settings!$B$341:C530,2,FALSE) -> 9 | E16: Fossil Fuel Combustion | F16: Combustion | G16: =VLOOKUP(F16,Settings!$B$163:D452,3,FALSE) -> C | H16: =VLOOKUP(F16,Settings!$B$163:D451,2,FALSE) -> 1 | I16: =VLOOKUP(F16,Settings!$B$163:F217,5,FALSE) -> 1 | J16: =_xlfn.TEXTJOIN("-",,D16,G16,B16) -> 9-C-8 | K16: =VLOOKUP(J16,Combustion!$J$103:$P$110,4,FALSE) -> 90085.662 | L16: =VLOOKUP(J16,Combustion!$J$103:$P$110,5,FALSE) -> 1.6038621 | M16: =VLOOKUP(J16,Combustion!$J$103:$P$110,6,FALSE) -> 0.16039131 | N16: 0 | O16: =VLOOKUP(J16,Combustion!$J$103:$P$110,7,FALSE) -> 90172.753 | P16: =O16/$O$195 -> 0.0044723076
B17: 9 | C17: Iron Making | D17: =VLOOKUP(C17,Settings!$B$341:C850,2,FALSE) -> 1 | E17: Process emission (Vent) | F17: Vent | G17: =VLOOKUP(F17,Settings!$B$163:D772,3,FALSE) -> V | H17: =VLOOKUP(F17,Settings!$B$163:D771,2,FALSE) -> 1 | I17: =VLOOKUP(F17,Settings!$B$163:F199,5,FALSE) -> 1 | J17: =_xlfn.TEXTJOIN("-",,D17,G17,B17) -> 1-V-9 | K17: =VLOOKUP(J17,Vent!$K$24:$M$31,3,FALSE) -> 3866055.4 | L17: 0 | M17: 0 | N17: 0 | O17: =K17 -> 3866055.4 | P17: =O17/$O$195 -> 0.19174516
B18: 10 | C18: Steel Making | D18: =VLOOKUP(C18,Settings!$B$341:C851,2,FALSE) -> 2 | E18: Process emission (Vent) | F18: Vent | G18: =VLOOKUP(F18,Settings!$B$163:D773,3,FALSE) -> V | H18: =VLOOKUP(F18,Settings!$B$163:D772,2,FALSE) -> 1 | I18: =VLOOKUP(F18,Settings!$B$163:F200,5,FALSE) -> 1 | J18: =_xlfn.TEXTJOIN("-",,D18,G18,B18) -> 2-V-10 | K18: =VLOOKUP(J18,Vent!$K$24:$M$31,3,FALSE) -> 427613.9 | L18: 0 | M18: 0 | N18: 0 | O18: =K18 -> 427613.9 | P18: =O18/$O$195 -> 0.021208412
B19: 11 | C19: Hot Rolling | D19: =VLOOKUP(C19,Settings!$B$341:C849,2,FALSE) -> 3 | E19: Process emission (Vent) | F19: Vent | G19: =VLOOKUP(F19,Settings!$B$163:D771,3,FALSE) -> V | H19: =VLOOKUP(F19,Settings!$B$163:D770,2,FALSE) -> 1 | I19: =VLOOKUP(F19,Settings!$B$163:F201,5,FALSE) -> 1 | J19: =_xlfn.TEXTJOIN("-",,D19,G19,B19) -> 3-V-11 | K19: =VLOOKUP(J19,Vent!$K$24:$M$31,3,FALSE) -> 0 | L19: 0 | M19: 0 | N19: 0 | O19: =K19 -> 0 | P19: =O19/$O$195 -> 0
B20: 12 | C20: Cold Rolling | D20: =VLOOKUP(C20,Settings!$B$341:C852,2,FALSE) -> 4 | E20: Process emission (Vent) | F20: Vent | G20: =VLOOKUP(F20,Settings!$B$163:D774,3,FALSE) -> V | H20: =VLOOKUP(F20,Settings!$B$163:D773,2,FALSE) -> 1 | I20: =VLOOKUP(F20,Settings!$B$163:F239,5,FALSE) -> 1 | J20: =_xlfn.TEXTJOIN("-",,D20,G20,B20) -> 4-V-12 | K20: =VLOOKUP(J20,Vent!$K$24:$M$31,3,FALSE) -> 0 | L20: 0 | M20: 0 | N20: 0 | O20: =K20 -> 0 | P20: =O20/$O$195 -> 0
B21: 13 | C21: Utility | D21: =VLOOKUP(C21,Settings!$B$341:C951,2,FALSE) -> 5 | E21: Process emission (Vent) | F21: Vent | G21: =VLOOKUP(F21,Settings!$B$163:D853,3,FALSE) -> V | H21: =VLOOKUP(F21,Settings!$B$163:D852,2,FALSE) -> 1 | I21: =VLOOKUP(F21,Settings!$B$163:F560,5,FALSE) -> 1 | J21: =_xlfn.TEXTJOIN("-",,D21,G21,B21) -> 5-V-13 | K21: =VLOOKUP(J21,Vent!$K$24:$M$31,3,FALSE) -> 0 | L21: 0 | M21: 0 | N21: 0 | O21: =K21 -> 0 | P21: =O21/$O$195 -> 0
B22: 14 | C22: Transportation | D22: =VLOOKUP(C22,Settings!$B$341:C995,2,FALSE) -> 6 | E22: Process emission (Vent) | F22: Vent | G22: =VLOOKUP(F22,Settings!$B$163:D897,3,FALSE) -> V | H22: =VLOOKUP(F22,Settings!$B$163:D896,2,FALSE) -> 1 | I22: =VLOOKUP(F22,Settings!$B$163:F604,5,FALSE) -> 1 | J22: =_xlfn.TEXTJOIN("-",,D22,G22,B22) -> 6-V-14 | K22: =VLOOKUP(J22,Vent!$K$24:$M$31,3,FALSE) -> 0 | L22: 0 | M22: 0 | N22: 0 | O22: =K22 -> 0 | P22: =O22/$O$195 -> 0
B23: 15 | C23: Maintenance | D23: =VLOOKUP(C23,Settings!$B$341:C996,2,FALSE) -> 7 | E23: Process emission (Vent) | F23: Vent | G23: =VLOOKUP(F23,Settings!$B$163:D898,3,FALSE) -> V | H23: =VLOOKUP(F23,Settings!$B$163:D897,2,FALSE) -> 1 | I23: =VLOOKUP(F23,Settings!$B$163:F605,5,FALSE) -> 1 | J23: =_xlfn.TEXTJOIN("-",,D23,G23,B23) -> 7-V-15 | K23: =VLOOKUP(J23,Vent!$K$24:$M$31,3,FALSE) -> 0 | L23: 0 | M23: 0 | N23: 0 | O23: =K23 -> 0 | P23: =O23/$O$195 -> 0
B24: 16 | C24: TAS | D24: =VLOOKUP(C24,Settings!$B$341:C997,2,FALSE) -> 9 | E24: Process emission (Vent) | F24: Vent | G24: =VLOOKUP(F24,Settings!$B$163:D899,3,FALSE) -> V | H24: =VLOOKUP(F24,Settings!$B$163:D898,2,FALSE) -> 1 | I24: =VLOOKUP(F24,Settings!$B$163:F606,5,FALSE) -> 1 | J24: =_xlfn.TEXTJOIN("-",,D24,G24,B24) -> 9-V-16 | K24: =VLOOKUP(J24,Vent!$K$24:$M$31,3,FALSE) -> 0 | L24: 0 | M24: 0 | N24: 0 | O24: =K24 -> 0 | P24: =O24/$O$195 -> 0
B25: 17 | C25: Iron Making | D25: =VLOOKUP(C25,Settings!$B$341:C858,2,FALSE) -> 1 | E25: Methane fugitive emission | F25: Fugitive | G25: =VLOOKUP(F25,Settings!$B$163:D780,3,FALSE) -> F | H25: =VLOOKUP(F25,Settings!$B$163:D779,2,FALSE) -> 1 | I25: =VLOOKUP(F25,Settings!$B$163:F196,5,FALSE) -> 1 | J25: =_xlfn.TEXTJOIN("-",,D25,G25,B25) -> 1-F-17 | K25: 0 | L25: =VLOOKUP(J25,Fugitive!$I$115:$L$122,3,FALSE) -> 11.115437 | M25: 0 | N25: 0 | O25: =VLOOKUP(J25,Fugitive!$I$115:$L$122,4,FALSE) -> 331.24004 | P25: =O25/$O$195 -> 1.6428547e-05
B26: 18 | C26: Steel Making | D26: =VLOOKUP(C26,Settings!$B$341:C872,2,FALSE) -> 2 | E26: Methane fugitive emission | F26: Fugitive | G26: =VLOOKUP(F26,Settings!$B$163:D794,3,FALSE) -> F | H26: =VLOOKUP(F26,Settings!$B$163:D793,2,FALSE) -> 1 | I26: =VLOOKUP(F26,Settings!$B$163:F196,5,FALSE) -> 1 | J26: =_xlfn.TEXTJOIN("-",,D26,G26,B26) -> 2-F-18 | K26: 0 | L26: =VLOOKUP(J26,Fugitive!$I$115:$L$122,3,FALSE) -> 7.8187593 | M26: 0 | N26: 0 | O26: =VLOOKUP(J26,Fugitive!$I$115:$L$122,4,FALSE) -> 232.99903 | P26: =O26/$O$195 -> 1.1556077e-05
B27: 19 | C27: Hot Rolling | D27: =VLOOKUP(C27,Settings!$B$341:C875,2,FALSE) -> 3 | E27: Methane fugitive emission | F27: Fugitive | G27: =VLOOKUP(F27,Settings!$B$163:D797,3,FALSE) -> F | H27: =VLOOKUP(F27,Settings!$B$163:D796,2,FALSE) -> 1 | I27: =VLOOKUP(F27,Settings!$B$163:F196,5,FALSE) -> 1 | J27: =_xlfn.TEXTJOIN("-",,D27,G27,B27) -> 3-F-19 | K27: 0 | L27: =VLOOKUP(J27,Fugitive!$I$115:$L$122,3,FALSE) -> 5.923259 | M27: 0 | N27: 0 | O27: =VLOOKUP(J27,Fugitive!$I$115:$L$122,4,FALSE) -> 176.51312 | P27: =O27/$O$195 -> 8.7545398e-06
B28: 20 | C28: Cold Rolling | D28: =VLOOKUP(C28,Settings!$B$341:C859,2,FALSE) -> 4 | E28: Methane fugitive emission | F28: Fugitive | G28: =VLOOKUP(F28,Settings!$B$163:D781,3,FALSE) -> F | H28: =VLOOKUP(F28,Settings!$B$163:D780,2,FALSE) -> 1 | I28: =VLOOKUP(F28,Settings!$B$163:F197,5,FALSE) -> 1 | J28: =_xlfn.TEXTJOIN("-",,D28,G28,B28) -> 4-F-20 | K28: 0 | L28: =VLOOKUP(J28,Fugitive!$I$115:$L$122,3,FALSE) -> 8.1441224 | M28: 0 | N28: 0 | O28: =VLOOKUP(J28,Fugitive!$I$115:$L$122,4,FALSE) -> 242.69485 | P28: =O28/$O$195 -> 1.2036962e-05
B29: 21 | C29: Utility | D29: =VLOOKUP(C29,Settings!$B$341:C860,2,FALSE) -> 5 | E29: Methane fugitive emission | F29: Fugitive | G29: =VLOOKUP(F29,Settings!$B$163:D782,3,FALSE) -> F | H29: =VLOOKUP(F29,Settings!$B$163:D781,2,FALSE) -> 1 | I29: =VLOOKUP(F29,Settings!$B$163:F198,5,FALSE) -> 1 | J29: =_xlfn.TEXTJOIN("-",,D29,G29,B29) -> 5-F-21 | K29: 0 | L29: =VLOOKUP(J29,Fugitive!$I$115:$L$122,3,FALSE) -> 24.914493 | M29: 0 | N29: 0 | O29: =VLOOKUP(J29,Fugitive!$I$115:$L$122,4,FALSE) -> 742.45189 | P29: =O29/$O$195 -> 3.6823465e-05
B30: 22 | C30: Transportation | D30: =VLOOKUP(C30,Settings!$B$341:C878,2,FALSE) -> 6 | E30: Methane fugitive emission | F30: Fugitive | G30: =VLOOKUP(F30,Settings!$B$163:D800,3,FALSE) -> F | H30: =VLOOKUP(F30,Settings!$B$163:D799,2,FALSE) -> 1 | I30: =VLOOKUP(F30,Settings!$B$163:F198,5,FALSE) -> 1 | J30: =_xlfn.TEXTJOIN("-",,D30,G30,B30) -> 6-F-22 | K30: 0 | L30: =VLOOKUP(J30,Fugitive!$I$115:$L$122,3,FALSE) -> 0 | M30: 0 | N30: 0 | O30: =VLOOKUP(J30,Fugitive!$I$115:$L$122,4,FALSE) -> 0 | P30: =O30/$O$195 -> 0
B31: 23 | C31: Maintenance | D31: =VLOOKUP(C31,Settings!$B$341:C861,2,FALSE) -> 7 | E31: Methane fugitive emission | F31: Fugitive | G31: =VLOOKUP(F31,Settings!$B$163:D783,3,FALSE) -> F | H31: =VLOOKUP(F31,Settings!$B$163:D782,2,FALSE) -> 1 | I31: =VLOOKUP(F31,Settings!$B$163:F236,5,FALSE) -> 1 | J31: =_xlfn.TEXTJOIN("-",,D31,G31,B31) -> 7-F-23 | K31: 0 | L31: =VLOOKUP(J31,Fugitive!$I$115:$L$122,3,FALSE) -> 1.575518 | M31: 0 | N31: 0 | O31: =VLOOKUP(J31,Fugitive!$I$115:$L$122,4,FALSE) -> 46.950437 | P31: =O31/$O$195 -> 2.3286058e-06
B32: 24 | C32: TAS | D32: =VLOOKUP(C32,Settings!$B$341:C862,2,FALSE) -> 9 | E32: Methane fugitive emission | F32: Fugitive | G32: =VLOOKUP(F32,Settings!$B$163:D784,3,FALSE) -> F | H32: =VLOOKUP(F32,Settings!$B$163:D783,2,FALSE) -> 1 | I32: =VLOOKUP(F32,Settings!$B$163:F238,5,FALSE) -> 1 | J32: =_xlfn.TEXTJOIN("-",,D32,G32,B32) -> 9-F-24 | K32: 0 | L32: =VLOOKUP(J32,Fugitive!$I$115:$L$122,3,FALSE) -> 2.3446234 | M32: 0 | N32: 0 | O32: =VLOOKUP(J32,Fugitive!$I$115:$L$122,4,FALSE) -> 69.869776 | P32: =O32/$O$195 -> 3.4653387e-06
B33: 25 | C33: Utility | D33: =VLOOKUP(C33,Settings!$B$341:C952,2,FALSE) -> 5 | E33: SF6 fugitive emission | F33: Fugitive | G33: =VLOOKUP(F33,Settings!$B$163:D854,3,FALSE) -> F | H33: =VLOOKUP(F33,Settings!$B$163:D853,2,FALSE) -> 1 | I33: =VLOOKUP(F33,Settings!$B$163:F561,5,FALSE) -> 1 | J33: =_xlfn.TEXTJOIN("-",,D33,G33,B33) -> 5-F-25 | K33: 0 | L33: 0 | M33: 0 | N33: =Fugitive!K49 -> 0.4 | O33: =Fugitive!L49 -> 9720 | P33: =O33/$O$195 -> 0.00048208387
B34: 26 | C34: Maintenance | D34: =VLOOKUP(C34,Settings!$B$341:C983,2,FALSE) -> 7 | E34: CO2 fire extinguishers | F34: Fugitive | G34: =VLOOKUP(F34,Settings!$B$163:D885,3,FALSE) -> F | H34: =VLOOKUP(F34,Settings!$B$163:D884,2,FALSE) -> 1 | I34: =VLOOKUP(F34,Settings!$B$163:F592,5,FALSE) -> 1 | J34: =_xlfn.TEXTJOIN("-",,D34,G34,B34) -> 7-F-26 | K34: =VLOOKUP(J34,Fugitive!$B$49:$M$67,11,FALSE) -> 46.864 | L34: 0 | M34: 0 | N34: 0 | O34: =VLOOKUP(J34,Fugitive!B49:L67,11,FALSE) -> 46.864 | P34: =O34/$O$195 -> 2.3243188e-06
B35: 27 | C35: Iron Making | D35: =VLOOKUP(C35,Settings!$B$341:C965,2,FALSE) -> 1 | E35: Non-energy product use (oil) | F35: Fugitive | G35: =VLOOKUP(F35,Settings!$B$163:D867,3,FALSE) -> F | H35: =VLOOKUP(F35,Settings!$B$163:D866,2,FALSE) -> 1 | I35: =VLOOKUP(F35,Settings!$B$163:F574,5,FALSE) -> 1 | J35: =_xlfn.TEXTJOIN("-",,D35,G35,B35) -> 1-F-27 | K35: =VLOOKUP(J35,Fugitive!$B$75:$L$90,11,FALSE) -> 90.114464 | L35: 0 | M35: 0 | N35: 0 | O35: =VLOOKUP(J35,Fugitive!$B$75:$L$90,11,FALSE) -> 90.114464 | P35: =O35/$O$195 -> 4.4694166e-06
B36: 28 | C36: Steel Making | D36: =VLOOKUP(C36,Settings!$B$341:C966,2,FALSE) -> 2 | E36: Non-energy product use (oil) | F36: Fugitive | G36: =VLOOKUP(F36,Settings!$B$163:D868,3,FALSE) -> F | H36: =VLOOKUP(F36,Settings!$B$163:D867,2,FALSE) -> 1 | I36: =VLOOKUP(F36,Settings!$B$163:F575,5,FALSE) -> 1 | J36: =_xlfn.TEXTJOIN("-",,D36,G36,B36) -> 2-F-28 | K36: =VLOOKUP(J36,Fugitive!$B$75:$L$90,11,FALSE) -> 252.45316 | L36: 0 | M36: 0 | N36: 0 | O36: =VLOOKUP(J36,Fugitive!$B$75:$L$90,11,FALSE) -> 252.45316 | P36: =O36/$O$195 -> 1.2520946e-05
B37: 29 | C37: Hot Rolling | D37: =VLOOKUP(C37,Settings!$B$341:C967,2,FALSE) -> 3 | E37: Non-energy product use (oil) | F37: Fugitive | G37: =VLOOKUP(F37,Settings!$B$163:D869,3,FALSE) -> F | H37: =VLOOKUP(F37,Settings!$B$163:D868,2,FALSE) -> 1 | I37: =VLOOKUP(F37,Settings!$B$163:F576,5,FALSE) -> 1 | J37: =_xlfn.TEXTJOIN("-",,D37,G37,B37) -> 3-F-29 | K37: =VLOOKUP(J37,Fugitive!$B$75:$L$90,11,FALSE) -> 436.21851 | L37: 0 | M37: 0 | N37: 0 | O37: =VLOOKUP(J37,Fugitive!$B$75:$L$90,11,FALSE) -> 436.21851 | P37: =O37/$O$195 -> 2.1635175e-05
B38: 30 | C38: Cold Rolling | D38: =VLOOKUP(C38,Settings!$B$341:C968,2,FALSE) -> 4 | E38: Non-energy product use (oil) | F38: Fugitive | G38: =VLOOKUP(F38,Settings!$B$163:D870,3,FALSE) -> F | H38: =VLOOKUP(F38,Settings!$B$163:D869,2,FALSE) -> 1 | I38: =VLOOKUP(F38,Settings!$B$163:F577,5,FALSE) -> 1 | J38: =_xlfn.TEXTJOIN("-",,D38,G38,B38) -> 4-F-30 | K38: =VLOOKUP(J38,Fugitive!$B$75:$L$90,11,FALSE) -> 1092.8 | L38: 0 | M38: 0 | N38: 0 | O38: =VLOOKUP(J38,Fugitive!$B$75:$L$90,11,FALSE) -> 1092.8 | P38: =O38/$O$195 -> 5.4199718e-05
B39: 31 | C39: Utility | D39: =VLOOKUP(C39,Settings!$B$341:C969,2,FALSE) -> 5 | E39: Non-energy product use (oil) | F39: Fugitive | G39: =VLOOKUP(F39,Settings!$B$163:D871,3,FALSE) -> F | H39: =VLOOKUP(F39,Settings!$B$163:D870,2,FALSE) -> 1 | I39: =VLOOKUP(F39,Settings!$B$163:F578,5,FALSE) -> 1 | J39: =_xlfn.TEXTJOIN("-",,D39,G39,B39) -> 5-F-31 | K39: =VLOOKUP(J39,Fugitive!$B$75:$L$90,11,FALSE) -> 7.7838992 | L39: 0 | M39: 0 | N39: 0 | O39: =VLOOKUP(J39,Fugitive!$B$75:$L$90,11,FALSE) -> 7.7838992 | P39: =O39/$O$195 -> 3.8605887e-07
B40: 32 | C40: Transportation | D40: =VLOOKUP(C40,Settings!$B$341:C970,2,FALSE) -> 6 | E40: Non-energy product use (oil) | F40: Fugitive | G40: =VLOOKUP(F40,Settings!$B$163:D872,3,FALSE) -> F | H40: =VLOOKUP(F40,Settings!$B$163:D871,2,FALSE) -> 1 | I40: =VLOOKUP(F40,Settings!$B$163:F579,5,FALSE) -> 1 | J40: =_xlfn.TEXTJOIN("-",,D40,G40,B40) -> 6-F-32 | K40: =VLOOKUP(J40,Fugitive!$B$75:$L$90,11,FALSE) -> 30.220538 | L40: 0 | M40: 0 | N40: 0 | O40: =VLOOKUP(J40,Fugitive!$B$75:$L$90,11,FALSE) -> 30.220538 | P40: =O40/$O$195 -> 1.4988512e-06
B41: 33 | C41: Maintenance | D41: =VLOOKUP(C41,Settings!$B$341:C971,2,FALSE) -> 7 | E41: Non-energy product use (oil) | F41: Fugitive | G41: =VLOOKUP(F41,Settings!$B$163:D873,3,FALSE) -> F | H41: =VLOOKUP(F41,Settings!$B$163:D872,2,FALSE) -> 1 | I41: =VLOOKUP(F41,Settings!$B$163:F580,5,FALSE) -> 1 | J41: =_xlfn.TEXTJOIN("-",,D41,G41,B41) -> 7-F-33 | K41: =VLOOKUP(J41,Fugitive!$B$75:$L$90,11,FALSE) -> 11.77726 | L41: 0 | M41: 0 | N41: 0 | O41: =VLOOKUP(J41,Fugitive!$B$75:$L$90,11,FALSE) -> 11.77726 | P41: =O41/$O$195 -> 5.8411801e-07
B42: 34 | C42: TAS | D42: =VLOOKUP(C42,Settings!$B$341:C972,2,FALSE) -> 9 | E42: Non-energy product use (oil) | F42: Fugitive | G42: =VLOOKUP(F42,Settings!$B$163:D874,3,FALSE) -> F | H42: =VLOOKUP(F42,Settings!$B$163:D873,2,FALSE) -> 1 | I42: =VLOOKUP(F42,Settings!$B$163:F581,5,FALSE) -> 1 | J42: =_xlfn.TEXTJOIN("-",,D42,G42,B42) -> 9-F-34 | K42: =VLOOKUP(J42,Fugitive!$B$75:$L$90,11,FALSE) -> 2.576552 | L42: 0 | M42: 0 | N42: 0 | O42: =VLOOKUP(J42,Fugitive!$B$75:$L$90,11,FALSE) -> 2.576552 | P42: =O42/$O$195 -> 1.2778952e-07
B43: 35 | C43: Iron Making | D43: =VLOOKUP(C43,Settings!$B$341:C973,2,FALSE) -> 1 | E43: Non-energy product use (grease) | F43: Fugitive | G43: =VLOOKUP(F43,Settings!$B$163:D875,3,FALSE) -> F | H43: =VLOOKUP(F43,Settings!$B$163:D874,2,FALSE) -> 1 | I43: =VLOOKUP(F43,Settings!$B$163:F582,5,FALSE) -> 1 | J43: =_xlfn.TEXTJOIN("-",,D43,G43,B43) -> 1-F-35 | K43: =VLOOKUP(J43,Fugitive!$B$75:$L$90,11,FALSE) -> 15.837393 | L43: 0 | M43: 0 | N43: 0 | O43: =VLOOKUP(J43,Fugitive!$B$75:$L$90,11,FALSE) -> 15.837393 | P43: =O43/$O$195 -> 7.8548885e-07
B44: 36 | C44: Steel Making | D44: =VLOOKUP(C44,Settings!$B$341:C974,2,FALSE) -> 2 | E44: Non-energy product use (grease) | F44: Fugitive | G44: =VLOOKUP(F44,Settings!$B$163:D876,3,FALSE) -> F | H44: =VLOOKUP(F44,Settings!$B$163:D875,2,FALSE) -> 1 | I44: =VLOOKUP(F44,Settings!$B$163:F583,5,FALSE) -> 1 | J44: =_xlfn.TEXTJOIN("-",,D44,G44,B44) -> 2-F-36 | K44: =VLOOKUP(J44,Fugitive!$B$75:$L$90,11,FALSE) -> 28.077342 | L44: 0 | M44: 0 | N44: 0 | O44: =VLOOKUP(J44,Fugitive!$B$75:$L$90,11,FALSE) -> 28.077342 | P44: =O44/$O$195 -> 1.3925549e-06
B45: 37 | C45: Hot Rolling | D45: =VLOOKUP(C45,Settings!$B$341:C975,2,FALSE) -> 3 | E45: Non-energy product use (grease) | F45: Fugitive | G45: =VLOOKUP(F45,Settings!$B$163:D877,3,FALSE) -> F | H45: =VLOOKUP(F45,Settings!$B$163:D876,2,FALSE) -> 1 | I45: =VLOOKUP(F45,Settings!$B$163:F584,5,FALSE) -> 1 | J45: =_xlfn.TEXTJOIN("-",,D45,G45,B45) -> 3-F-37 | K45: =VLOOKUP(J45,Fugitive!$B$75:$L$90,11,FALSE) -> 36.549009 | L45: 0 | M45: 0 | N45: 0 | O45: =VLOOKUP(J45,Fugitive!$B$75:$L$90,11,FALSE) -> 36.549009 | P45: =O45/$O$195 -> 1.8127251e-06
B46: 38 | C46: Cold Rolling | D46: =VLOOKUP(C46,Settings!$B$341:C976,2,FALSE) -> 4 | E46: Non-energy product use (grease) | F46: Fugitive | G46: =VLOOKUP(F46,Settings!$B$163:D878,3,FALSE) -> F | H46: =VLOOKUP(F46,Settings!$B$163:D877,2,FALSE) -> 1 | I46: =VLOOKUP(F46,Settings!$B$163:F585,5,FALSE) -> 1 | J46: =_xlfn.TEXTJOIN("-",,D46,G46,B46) -> 4-F-38 | K46: =VLOOKUP(J46,Fugitive!$B$75:$L$90,11,FALSE) -> 3.3952116 | L46: 0 | M46: 0 | N46: 0 | O46: =VLOOKUP(J46,Fugitive!$B$75:$L$90,11,FALSE) -> 3.3952116 | P46: =O46/$O$195 -> 1.6839267e-07
...

Sheet Tables & Graphs
B7: Click to see the results of each section. | H7: Total | K7: Area Comparison
H9: Iron Making | K9: Steel Making | N9: Hot Rolling | Q9: Cold Rolling
H11: Transportation | K11: Maintenance | N11: Utility | Q11: TAS
B13: Total
B20: Emission of Areas
B21: Area | C21: Code | E21: Emission (tCO2e/yr) | F21: Share (%)
B22: Iron Making | C22: =VLOOKUP(B22,Settings!$B$341:C348,2,FALSE) -> 1 | E22: =SUMIF(Inventory!$C$9:$C$194,B22,Inventory!$O$9:$O$194) -> 7182736.2 | F22: =E22/$E$30 -> 0.35624293
B23: Steel Making | C23: =VLOOKUP(B23,Settings!$B$341:C349,2,FALSE) -> 2 | E23: =SUMIF(Inventory!$C$9:$C$194,B23,Inventory!$O$9:$O$194) -> 9305750 | F23: =E23/$E$30 -> 0.46153827
B24: Hot Rolling | C24: =VLOOKUP(B24,Settings!$B$341:C350,2,FALSE) -> 3 | E24: =SUMIF(Inventory!$C$9:$C$194,B24,Inventory!$O$9:$O$194) -> 463713.2 | F24: =E24/$E$30 -> 0.022998832
B25: Cold Rolling | C25: =VLOOKUP(B25,Settings!$B$341:C351,2,FALSE) -> 4 | E25: =SUMIF(Inventory!$C$9:$C$194,B25,Inventory!$O$9:$O$194) -> 260650.53 | F25: =E25/$E$30 -> 0.012927512
B26: Utility | C26: =VLOOKUP(B26,Settings!$B$341:C352,2,FALSE) -> 5 | E26: =SUMIF(Inventory!$C$9:$C$194,B26,Inventory!$O$9:$O$194) -> 2099578.7 | F26: =E26/$E$30 -> 0.10413303
B27: Transportation | C27: =VLOOKUP(B27,Settings!$B$341:C353,2,FALSE) -> 6 | E27: =SUMIF(Inventory!$C$9:$C$194,B27,Inventory!$O$9:$O$194) -> 35746.127 | F27: =E27/$E$30 -> 0.0017729045
B28: Maintenance | C28: =VLOOKUP(B28,Settings!$B$341:C362,2,FALSE) -> 7 | E28: =SUMIF(Inventory!$C$9:$C$194,B28,Inventory!$O$9:$O$194) -> 74832.07 | F28: =E28/$E$30 -> 0.0037114541
B29: TAS | C29: =VLOOKUP(B29,Settings!$B$341:C364,2,FALSE) -> 9 | E29: =SUMIF(Inventory!$C$9:$C$194,B29,Inventory!$O$9:$O$194) -> 739460.05 | F29: =E29/$E$30 -> 0.036675078
B30: Sum | E30: =_xlfn.AGGREGATE(9,6,E22:E29) -> 20162467 | F30: =SUM(F22:F29) -> 1
B40: Emissions by Types
B41: Emission type | C41: Sign | D41: Category | E41: Emission (tCO2e/yr) | F41: Share (%)
B42: Combustion | C42: =VLOOKUP(B42,Settings!$B$163:$D$180,3,FALSE) -> C | D42: =VLOOKUP(B42,Settings!$B$163:$C$180,2,FALSE) -> 1 | E42: =SUMIF(Inventory!$G$9:$G$194,C42,Inventory!$O$9:$O$194) -> 1296747 | F42: =E42/$E$58 -> 0.064314898
B43: Vent | C43: =VLOOKUP(B43,Settings!$B$163:$D$180,3,FALSE) -> V | D43: =VLOOKUP(B43,Settings!$B$163:$C$180,2,FALSE) -> 1 | E43: =SUMIF(Inventory!$G$9:$G$194,C43,Inventory!$O$9:$O$194) -> 4293669.3 | F43: =E43/$E$58 -> 0.21295357
B44: Fugitive | C44: =VLOOKUP(B44,Settings!$B$163:$D$180,3,FALSE) -> F | D44: =VLOOKUP(B44,Settings!$B$163:$C$180,2,FALSE) -> 1 | E44: =SUMIF(Inventory!$G$9:$G$194,C44,Inventory!$O$9:$O$194) -> 13618.733 | F44: =E44/$E$58 -> 0.00067544973
B45: Mobile Combustion | C45: =VLOOKUP(B45,Settings!$B$163:$D$180,3,FALSE) -> M | D45: =VLOOKUP(B45,Settings!$B$163:$C$180,2,FALSE) -> 1 | E45: =SUMIF(Inventory!$G$9:$G$194,C45,Inventory!$O$9:$O$194) -> 49101.16 | F45: =E45/$E$58 -> 0.0024352754
B46: Waste Onsite | C46: =VLOOKUP(B46,Settings!$B$163:$D$180,3,FALSE) -> W | D46: =VLOOKUP(B46,Settings!$B$163:$C$180,2,FALSE) -> 1 | E46: =SUMIF(Inventory!$G$9:$G$194,C46,Inventory!$O$9:$O$194) -> 90516.963 | F46: =E46/$E$58 -> 0.0044893794
B47: Wastewater | C47: =VLOOKUP(B47,Settings!$B$163:$D$180,3,FALSE) -> Y | D47: =VLOOKUP(B47,Settings!$B$163:$C$180,2,FALSE) -> 1 | E47: =SUMIF(Inventory!$G$9:$G$194,C47,Inventory!$O$9:$O$194) -> 597.43271 | F47: =E47/$E$58 -> 2.9630933e-05
B48: Electricity | C48: =VLOOKUP(B48,Settings!$B$163:$D$180,3,FALSE) -> E | D48: =VLOOKUP(B48,Settings!$B$163:$C$180,2,FALSE) -> 2 | E48: =SUMIF(Inventory!$G$9:$G$194,C48,Inventory!$O$9:$O$194) -> 4539539.9 | F48: =E48/$E$58 -> 0.22514804
B49: Up-Transportation | C49: =VLOOKUP(B49,Settings!$B$163:$D$180,3,FALSE) -> T | D49: =VLOOKUP(B49,Settings!$B$163:$C$180,2,FALSE) -> 3 | E49: =SUMIF(Inventory!$G$9:$G$194,C49,Inventory!$O$9:$O$194) -> 488422.61 | F49: =E49/$E$58 -> 0.024224348
B50: Down-Transportation | C50: =VLOOKUP(B50,Settings!$B$163:$D$180,3,FALSE) -> D | D50: =VLOOKUP(B50,Settings!$B$163:$C$180,2,FALSE) -> 3 | E50: =SUMIF(Inventory!$G$9:$G$194,C50,Inventory!$O$9:$O$194) -> 0 | F50: =E50/$E$58 -> 0
B51: Commuting | C51: =VLOOKUP(B51,Settings!$B$163:$D$180,3,FALSE) -> P | D51: =VLOOKUP(B51,Settings!$B$163:$C$180,2,FALSE) -> 3 | E51: =SUMIF(Inventory!$G$9:$G$194,C51,Inventory!$O$9:$O$194) -> 33906.774 | F51: =E51/$E$58 -> 0.0016816779
B52: Business travel | C52: =VLOOKUP(B52,Settings!$B$163:$D$180,3,FALSE) -> B | D52: =VLOOKUP(B52,Settings!$B$163:$C$180,2,FALSE) -> 3 | E52: =SUMIF(Inventory!$G$9:$G$194,C52,Inventory!$O$9:$O$194) -> 704949.5 | F52: =E52/$E$58 -> 0.034963455
B53: Purchased Material | C53: =VLOOKUP(B53,Settings!$B$163:$D$180,3,FALSE) -> R | D53: =VLOOKUP(B53,Settings!$B$163:$C$180,2,FALSE) -> 4 | E53: =SUMIF(Inventory!$G$9:$G$194,C53,Inventory!$O$9:$O$194) -> 7604433.7 | F53: =E53/$E$58 -> 0.3771579
... B57: Energy related | C57: =VLOOKUP(B57,Settings!$B$163:$D$180,3,FALSE) -> N | D57: =VLOOKUP(B57,Settings!$B$163:$C$180,2,FALSE) -> 4 | E57: =SUMIF(Inventory!$G$9:$G$194,C57,Inventory!$O$9:$O$194) -> 1001844.7 | F57: =E57/$E$58 -> 0.049688597
B58: Sum | E58: =_xlfn.AGGREGATE(9,6,E42:E57) -> 20162467 | F58: =SUM(F42:F57) -> 1
B66: Emissions by Categories
B67: Category | E67: Emission (tCO2e/yr) | F67: Share (%)
B68: 1 | E68: =SUMIF(Inventory!$H$9:$H$194,B68,Inventory!$O$9:$O$194) -> 5744250.6 | F68: =E68/$E$74 -> 0.2848982
B69: 2 | E69: =SUMIF(Inventory!$H$9:$H$194,B69,Inventory!$O$9:$O$194) -> 4539539.9 | F69: =E69/$E$74 -> 0.22514804
B70: 3 | E70: =SUMIF(Inventory!$H$9:$H$194,B70,Inventory!$O$9:$O$194) -> 1227278.9 | F70: =E70/$E$74 -> 0.06086948
B71: 4 | E71: =SUMIF(Inventory!$H$9:$H$194,B71,Inventory!$O$9:$O$194) -> 8651397.6 | F71: =E71/$E$74 -> 0.42908428
B72: 5 | E72: =SUMIF(Inventory!$H$9:$H$194,B72,Inventory!$O$9:$O$194) -> 0 | F72: =E72/$E$74 -> 0
B73: 6 | E73: =SUMIF(Inventory!$H$9:$H$194,B73,Inventory!$O$9:$O$194) -> 0 | F73: =E73/$E$74 -> 0
B74: Sum | E74: =_xlfn.AGGREGATE(9,6,E68:E73) -> 20162467 | F74: =SUM(F68:F73) -> 1
...

Sheet Life Cycle
Y8: Electrode | Z8: Upstream Tran. | AA8: Electrode | AB8: Production | AC8: Raw material | AD8: Extraction
Y10: Briquett | Z10: Upstream Tran. | AA10: Briquett | AB10: Production | AC10: Raw material | AD10: Extraction
B12: Legend | D12: Outside of the boundary | Y12: Sponge iron | Z12: Upstream Tran. | AA12: Sponge iron | AB12: Production | AC12: Iron ore | AD12: Extraction
D14: Inside the boundary | Y14: Electrode | Z14: Upstream Tran. | AA14: Electrode | AB14: Production | AC14: Raw material | AD14: Extraction
Y16: Lime | Z16: Upstream Tran. | AA16: Lime | AB16: Production | AC16: Lime stone | AD16: Extraction
Y18: Coke | Z18: Upstream Tran. | AA18: Coke | AB18: Production | AC18: Raw material | AD18: Extraction
Y20: Graphite | Z20: Upstream Tran. | AA20: Graphite | AB20: Production | AC20: Raw material | AD20: Extraction
Y22: Scrap | Z22: Upstream Tran. | AA22: Scrap | AB22: Gathering
Y24: Gasoil | Z24: Upstream Tran. | AA24: Gasoil | AB24: Production | AC24: Oil | AD24: Extraction
Y26: Natural gas | Z26: Upstream Tran. | AA26: Natural gas | AB26: Production | AC26: Natural gas | AD26: Extraction
B29: Sale | J29: Molten slab 1 | K29: Ladle Furnaces | Y29: Dolomite | Z29: Upstream Tran. | AA29: Dolomite | AB29: Production | AC29: Dolomite stone | AD29: Extraction
B31: Store | D31: Slab | E31: Slab Cooling | G31: Slab (Unfinished) | H31: Casting | M31: Molten steel | N31: EAFs | P31: Dolomite | Q31: Dolomite Making | Y31: Dolomite stone | Z31: Upstream Tran. | AC31: Dolomite stone | AD31: Extraction
J33: Molten slab 2 | K33: De-gassing | T33: Lime | U33: Lime Making | Y33: Lime stone | Z33: Upstream Tran. | AC33: Lime stone | AD33: Extraction
Y35: Binder | Z35: Upstream Tran. | AA35: Binder | AB35: Production | AC35: Raw material | AD35: Extraction
P37: Briquett | Q37: Briquetting | R37: Hydrated lime | S37: Lime Dehydration | T37: Lime powder
L38: Sale | M38: Slag
R39: Powder
H42: Sale
P44: Sponge iron | Q44: DRI | Y44: Natural gas | Z44: Upstream Tran. | AA44: Natural gas | AB44: Production | AC44: Natural gas | AD44: Extraction
I45: Hot Coil (Temper) | K45: Sale
E48: Hot Rolling Mill | F48: Hot Rolled Coil | H48: Light Shearing 1 | I48: Hot Sheet (Light 1) | K48: Sale | Y48: Bentonite | Z48: Upstream Tran. | AA48: Bentonite | AB48: Production | AC48: Raw material | AD48: Extraction
R49: Pellet | S49: Pelletizing
U50: Concentrate | Y50: Concentrate | Z50: Upstream Tran. | AA50: Concentrate | AB50: Production | AC50: Iron ore | AD50: Extraction
H51: Light Shearing 2 | I51: Hot Sheet (Light 2) | K51: Sale
U53: Pellet | V53: Yard | Y53: Pellet | Z53: Upstream Tran. | AA53: Pellet | AB53: Production | AC53: Iron ore | AD53: Extraction
H54: Heavy Shearing | I54: Hot Sheet (Heavy) | K54: Sale
H57: Skin Pass Mill | I57: Hot Coil (Skin) | K57: Sale
K68: Sale | N68: Sale | Q68: Sale | S68: Sale | U68: Sale
R74: Full Hard Rolled Coil 1 | V74: Pickled Oxide Powder
L76: Color Coated Coil | M76: Coating Line | O76: Galvanized Coil | P76: Galvanizing Line | R76: Full Hard Coil 1 | S76: Tandem Mill | V76: Pickled Coil | W76: Pickling Line 1,2 | Y76: HCl | Z76: Upstream Tran. | AA76: HCl | AB76: Production | AC76: Raw material | AD76: Extraction
Y78: Zinc | Z78: Upstream Tran. | AA78: Zinc | AB78: Production | AC78: Raw material | AD78: Extraction
Y80: Paint | Z80: Upstream Tran. | AA80: Paint | AB80: Production | AC80: Raw material | AD80: Extraction
B81: Sale | F81: Cold Rolled Coil | G81: Corrective Line 1-4 | O81: Annealed Coil 1 | P81: Box Annealing 1
J82: Cold Rolled Oiled Coil
B85: Sale | F85: Cold Rolled Sheet (Light) | G85: Light Shearing | J85: Cold Non-Oiled Coil | K85: Skin Pass 1,2 | O85: Annealed Coil 2 | P85: Box Annealing 2
B89: Sale | F89: Cold Rolled Sheet (Heavy) | G89: Heavy Shearing | L89: Annealed Coil 3 | M89: Box Annealing 3 | O89: Cleaned Coil | P89: Electrolytic Cleaning
B93: Sale | I93: Black Plate Coil | J93: Temper Mill | L93: Annealed Coil | R93: Full Hard Coil 2 | S93: Two Stand Mill
B97: Sale | R97: Full Hard Rolled Coil 2
B101: Sale | F101: Tin Plated Coil | G101: Tinning Line | I101: Cold Coil Temper Mill
Y104: Tin | Z104: Upstream Tran. | AA104: Tin | AB104: Production | AC104: Raw material | AD104: Extraction
...

Sheet Carbon Footprints
B7: Click to see the results of each product. | I7: Slab | L7: Hot Coil (Skin) | O7: Black Plate Coil | R7: Tin Plated Sheet
I9: Hot Rolled Coil | L9: Pickled Coil | O9: Cold Rolled Coil | R9: Galvanized Coil
I11: Hot Coil (Temper) | L11: Full Hard Rolled Coil | O11: Cold Rolled Sheet | R11: Color Coated Coil
I13: Hot Rolled Sheet | L13: Cold Rolled Oiled Coil | O13: Tin Plated Coil | R13: Comparison
B16: Comparison | D16: مقایسه محصولات
B20: Company | C20: No. | D20: Product | E20: Product | F20: CFP (tCO2e/ton)
B21: MSC | C21: 1 | D21: تختال | E21: Slab | F21: =VLOOKUP(E21,'Units CF'!$C$90:$E$136,3,FALSE) -> 2.3301682
C22: 2 | D22: کلاف گرم | E22: Hot Rolled Coil | F22: =VLOOKUP(E22,'Units CF'!$C$90:$E$136,3,FALSE) -> 2.4846049
C23: 3 | D23: کلاف گرم (تمپر) | E23: Hot Coil (Temper) | F23: =VLOOKUP(E23,'Units CF'!$C$90:$E$136,3,FALSE) -> 2.8950544
C24: 4 | D24: ورق گرم | E24: Hot Rolled Sheet | F24: =VLOOKUP(E24,'Units CF'!$C$90:$E$136,3,FALSE) -> 2.7318012
C25: 5 | D25: کلاف گرم (اسکین) | E25: Hot Coil (Skin) | F25: =VLOOKUP(E25,'Units CF'!$C$90:$E$136,3,FALSE) -> 2.5594019
C26: 6 | D26: کلاف اسیدشویی | E26: Pickled Coil | F26: =VLOOKUP(E26,'Units CF'!$C$90:$E$136,3,FALSE) -> 2.6163427
C27: 7 | D27: کلاف خام | E27: Full Hard Rolled Coil | F27: =VLOOKUP(E27,'Units CF'!$C$90:$E$136,3,FALSE) -> 2.7418557
C28: 8 | D28: کلاف سرد روغنی | E28: Cold Rolled Oiled Coil | F28: =VLOOKUP(E28,'Units CF'!$C$90:$E$136,3,FALSE) -> 2.8652756
C29: 9 | D29: کلاف سیاه | E29: Black Plate Coil | F29: =VLOOKUP(E29,'Units CF'!$C$90:$E$136,3,FALSE) -> 3.2725871
C30: 10 | D30: کلاف سرد | E30: Cold Rolled Coil | F30: =VLOOKUP(E30,'Units CF'!$C$90:$E$136,3,FALSE) -> 2.9579956
C31: 11 | D31: ورق سرد | E31: Cold Rolled Sheet | F31: =VLOOKUP(E31,'Units CF'!$C$90:$E$136,3,FALSE) -> 2.970992
C32: 12 | D32: کلاف قلع اندود | E32: Tin Plated Coil | F32: =VLOOKUP(E32,'Units CF'!$C$90:$E$136,3,FALSE) -> 3.5098788
C33: 13 | D33: ورق قلع اندود | E33: Tin Plated Sheet | F33: =VLOOKUP(E33,'Units CF'!$C$90:$E$136,3,FALSE) -> 3.5975776
... C35: 15 | D35: کلاف رنگی | E35: Color Coated Coil | F35: =VLOOKUP(E35,'Units CF'!$C$90:$E$136,3,FALSE) -> 3.1282025
B38: توجه 1: ردپای کربن ورق گرم، متوسط وزنی ردپای کربن ورق‏های گرم خروجی از خطوط برش سبک 1 و 2 و سنگین است.
B39: توجه 2: ردپای کربن کلاف خام، متوسط وزنی ردپای کربن کلاف‏های خام خروجی از خطوط تاندم میل و نورد دو قفسه‏ای است.
B40: توجه 3: ردپای کربن ورق سرد، متوسط وزنی ردپای کربن ورق‏های سرد خروجی از خطوط برش سبک و سنگین است.
B44: Slab | D44: تختال
B48: Product | C48: Production | D48: Unit Process | E48: Unit Process | F48: Upstream Emission | G48: Direct Emission | H48: Utility Emission | I48: Total Emission | J48: Upstream CF | K48: Direct CF | L48: Utility CF | M48: Total CFP | N48: Share
C49: (ton) | F49: tCO2e | G49: tCO2e | H49: tCO2e | I49: tCO2e | J49: tCO2e/ton | K49: tCO2e/ton | L49: tCO2e/ton | M49: tCO2e/ton | N49: %
B50: Slab | C50: =SUM('Units CF'!F32:F34) -> 7299999.9 | D50: انباشت و برداشت | E50: Yard | F50: =SUM('Units CF'!O13:U14)*(1-'Units CF'!I28) -> 310622.44 | G50: =SUM('Units CF'!V13:AA14)*(1-'Units CF'!I28) -> 6405.1041 | H50: =SUM('Units CF'!AB13:AH14)*(1-'Units CF'!I28) -> 44047.5 | I50: =SUM(F50:H50) -> 361075.04 | J50: =F50/$C$50 -> 0.04255102 | K50: =G50/$C$50 -> 0.00087741153 | L50: =H50/$C$50 -> 0.0060339042 | M50: =SUM(J50:L50) -> 0.049462335 | N50: =M50/$M$62 -> 0.021226938
D51: آهک‏سازی | E51: Lime Plant | F51: =SUM('Units CF'!O15:U16)*('Units CF'!I15+'Units CF'!I16*('Units CF'!I17))*(1-'Units CF'!I28) -> 270063.69 | G51: =SUM('Units CF'!V15:AA16)*('Units CF'!I15+'Units CF'!I16*('Units CF'!I17))*(1-'Units CF'!I28) -> 216678 | H51: =SUM('Units CF'!AB15:AH16)*('Units CF'!I15+'Units CF'!I16*('Units CF'!I17))*(1-'Units CF'!I28) -> 12138.086 | I51: =SUM(F51:H51) -> 498879.78 | J51: =F51/$C$50 -> 0.036995027 | K51: =G51/$C$50 -> 0.029681918 | L51: =H51/$C$50 -> 0.0016627516 | M51: =SUM(J51:L51) -> 0.068339697 | N51: =M51/$M$62 -> 0.029328225
D52: تولید آهک هیدراته | E52: Lime Dehydration | F52: =SUM('Units CF'!O17:U20)*('Units CF'!I17)*(1-'Units CF'!I28) -> 1.363213 | G52: =SUM('Units CF'!V17:AA20)*('Units CF'!I17)*(1-'Units CF'!I28) -> 90.924524 | H52: =SUM('Units CF'!AB17:AH20)*('Units CF'!I17)*(1-'Units CF'!I28) -> 852.19467 | I52: =SUM(F52:H52) -> 944.48241 | J52: =F52/$C$50 -> 1.8674151e-07 | K52: =G52/$C$50 -> 1.2455414e-05 | L52: =H52/$C$50 -> 0.000116739 | M52: =SUM(J52:L52) -> 0.00012938115 | N52: =M52/$M$62 -> 5.5524385e-05
D53: دولومیت‏سازی | E53: Dolomite Plant | F53: =SUM('Units CF'!O21:U21)*(1-'Units CF'!I28) -> 12240.6 | G53: =SUM('Units CF'!V21:AA21)*(1-'Units CF'!I28) -> 118434.93 | H53: =SUM('Units CF'!AB21:AH21)*(1-'Units CF'!I28) -> 6272.2993 | I53: =SUM(F53:H53) -> 136947.83 | J53: =F53/$C$50 -> 0.0016767945 | K53: =G53/$C$50 -> 0.016223963 | L53: =H53/$C$50 -> 0.0008592191 | M53: =SUM(J53:L53) -> 0.018759976 | N53: =M53/$M$62 -> 0.008050911
D54: گندله‏سازی | E54: Pelletizing | F54: =SUM('Units CF'!O22:U22)*(1-'Units CF'!I28) -> 375799.34 | G54: =SUM('Units CF'!V22:AA22)*(1-'Units CF'!I28) -> 91439.218 | H54: =SUM('Units CF'!AB22:AH22)*(1-'Units CF'!I28) -> 136627.88 | I54: =SUM(F54:H54) -> 603866.44 | J54: =F54/$C$50 -> 0.051479363 | K54: =G54/$C$50 -> 0.01252592 | L54: =H54/$C$50 -> 0.018716148 | M54: =SUM(J54:L54) -> 0.082721431 | N54: =M54/$M$62 -> 0.035500198
D55: احیای مستقیم | E55: Direct Reduction | F55: =SUM('Units CF'!O23:U24)*(1-'Units CF'!I28) -> 766883.58 | G55: =SUM('Units CF'!V23:AA24)*(1-'Units CF'!I28) -> 3441657.1 | H55: =SUM('Units CF'!AB23:AH24)*(1-'Units CF'!I28) -> 651988.71 | I55: =SUM(F55:H55) -> 4860529.4 | J55: =F55/$C$50 -> 0.10505255 | K55: =G55/$C$50 -> 0.47145989 | L55: =H55/$C$50 -> 0.089313523 | M55: =SUM(J55:L55) -> 0.66582595 | N55: =M55/$M$62 -> 0.28574159
D56: بریکت‏سازی | E56: Briquetting | F56: =SUM('Units CF'!O25:U25)*(1-'Units CF'!I28) -> 628859.53 | G56: =SUM('Units CF'!V25:AA25)*(1-'Units CF'!I28) -> 28.920231 | H56: =SUM('Units CF'!AB25:AH25)*(1-'Units CF'!I28) -> 7399.2998 | I56: =SUM(F56:H56) -> 636287.75 | J56: =F56/$C$50 -> 0.086145143 | K56: =G56/$C$50 -> 3.9616755e-06 | L56: =H56/$C$50 -> 0.0010136027 | M56: =SUM(J56:L56) -> 0.087162708 | N56: =M56/$M$62 -> 0.037406188
D57: کوره‏های قوس | E57: EAF | F57: =SUM('Units CF'!O26:U28)*(1-'Units CF'!I28) -> 5206838.4 | G57: =SUM('Units CF'!V26:AA28)*(1-'Units CF'!I28) -> 440642.71 | H57: =SUM('Units CF'!AB26:AH28)*(1-'Units CF'!I28) -> 3717721.1 | I57: =SUM(F57:H57) -> 9365202.3 | J57: =F57/$C$50 -> 0.71326555 | K57: =G57/$C$50 -> 0.060362017 | L57: =H57/$C$50 -> 0.50927688 | M57: =SUM(J57:L57) -> 1.2829044 | N57: =M57/$M$62 -> 0.55056303
D58: گاززدایی | E58: Degassing | F58: =SUM('Units CF'!O29:U29) -> 11812.106 | G58: =SUM('Units CF'!V29:AA29) -> 2453.3686 | H58: =SUM('Units CF'!AB29:AH29) -> 24466.651 | I58: =SUM(F58:H58) -> 38732.126 | J58: =F58/$C$50 -> 0.0016180968 | K58: =G58/$C$50 -> 0.0003360779 | L58: =H58/$C$50 -> 0.0033515961 | M58: =SUM(J58:L58) -> 0.0053057708 | N58: =M58/$M$62 -> 0.0022769905
D59: کوره‏های پاتیلی | E59: Ladle Furnaces | F59: =SUM('Units CF'!O30:U30) -> 186580.02 | G59: =SUM('Units CF'!V30:AA30) -> 13086.121 | H59: =SUM('Units CF'!AB30:AH30) -> 154343.2 | I59: =SUM(F59:H59) -> 354009.34 | J59: =F59/$C$50 -> 0.025558907 | K59: =G59/$C$50 -> 0.0017926194 | L59: =H59/$C$50 -> 0.021142904 | M59: =SUM(J59:L59) -> 0.048494431 | N59: =M59/$M$62 -> 0.020811558
D60: ریخته‏گری مداوم | E60: Continuous Casting | F60: =SUM('Units CF'!O31:U31) -> 6449.8678 | G60: =SUM('Units CF'!V31:AA31) -> 16327.933 | H60: =SUM('Units CF'!AB31:AH31) -> 90348.613 | I60: =SUM(F60:H60) -> 113126.41 | J60: =F60/$C$50 -> 0.00088354355 | K60: =G60/$C$50 -> 0.0022367032 | L60: =H60/$C$50 -> 0.012376523 | M60: =SUM(J60:L60) -> 0.015496769 | N60: =M60/$M$62 -> 0.0066504939
D61: آماده‏سازی و خنک‏کننده شمش | E61: Slab Conditioning | F61: =SUM('Units CF'!O32:U34) -> 2058.4996 | G61: =SUM('Units CF'!V32:AA34) -> 2936.0987 | H61: =SUM('Units CF'!AB32:AH34) -> 35631.892 | I61: =SUM(F61:H61) -> 40626.49 | J61: =F61/$C$50 -> 0.00028198625 | K61: =G61/$C$50 -> 0.00040220532 | L61: =H61/$C$50 -> 0.0048810811 | M61: =SUM(J61:L61) -> 0.0055652727 | N61: =M61/$M$62 -> 0.0023883567
E62: Sum | F62: =SUM(F50:F61) -> 7778209.5 | G62: =SUM(G50:G61) -> 4350180.4 | H62: =SUM(H50:H61) -> 4881837.4 | I62: =SUM(I50:I61) -> 17010227 | J62: =SUM(J50:J61) -> 1.0655082 | K62: =SUM(K50:K61) -> 0.59591514 | L62: =SUM(L50:L61) -> 0.66874487 | M62: =SUM(M50:M61) -> 2.3301682 | N62: =SUM(N50:N61) -> 1
E63: % | J63: =J62/M62 -> 0.45726664 | K63: =K62/M62 -> 0.25573911 | L63: =L62/M62 -> 0.28699425
...

Sheet Section 1
B7: Section 1: GHG Emission Inventory of MSC Complex
B8: Sheet Name | C8: Notes
B9: Combustion | C9: Details of Combustion Emission Source Calculations
B10: Vent | C10: Details of Process Emission Source Calculations
B11: Fugitive | C11: Details of Fugitive Emission Calculations
B12: Electricity | C12: Details of Electricity Emission Calculations
B13: On-Site Transportation | C13: Details of On-Site Transportation Emission Calculations
B14: Upstream Transportation | C14: Details of Transportation (Upstream) Emission Calculations
B15: Downstream Transportation | C15: Details of Transportation (Downstream) Emission Calculations
B16: Employee Commuting | C16: Details of Employee Commuting Emission Calculations
B17: Business Travel | C17: Details of Business Travel (Domestic & International) Emission Calculations
B18: Purchased Material | C18: Details of Purchased Material Emission Calculations
B19: Ancillary Input | C19: Details of Ancillary Input Emission Calculations
... B23: Energy Related | C23: Details of Energy-Related Emission Calculations

Sheet Combustion
B7: Combustion
B8: Area | C8: Unit Process | D8: Cost Center Code | E8: Cost Item Code | F8: Annual Consumption | G8: Unit | H8: Fuel Type | I8: LHV | J8: EF | M8: Emission | Q8: Data Source of Annaul Consumption
J9: CO2 | K9: CH4 | L9: N2O | M9: CO2 | N9: CH4 | O9: N2O | P9: Total
I10: (GJ/Unit) | J10: (tCO2/GJ) | K10: (tCH4/GJ) | L10: (tN2O/GJ) | M10: (tCO2/y) | N10: (tCH4/y) | O10: (tN2O/y) | P10: (tCO2e/y)
B11: TAS | C11: All cost centers | E11: 10200 | F11: 0.016 | G11: =VLOOKUP(H11,Settings!$B$30:$F$36,5,0) -> ton | H11: Methane | I11: =VLOOKUP(H11,Settings!$B$30:$C$36,2,FALSE) -> 5 | J11: =VLOOKUP(H11,Settings!$B$46:$E$52,2,FALSE) -> 7 | K11: =VLOOKUP(H11,Settings!$B$46:$E$52,3,FALSE) -> 1e-06 | L11: =VLOOKUP(H11,Settings!$B$46:$E$52,4,FALSE) -> 1e-07 | M11: =F11*I11*J11 -> 0.56 | N11: =F11*I11*K11 -> 8e-08 | O11: =F11*I11*L11 -> 8e-09 | P11: =M11+(N11*Settings!$C$24)+(O11*Settings!$D$24) -> 0.56000434 | Q11: Purchase Order
B12: Iron Making | C12: All cost centers | E12: 10203 | F12: 2.387 | G12: =VLOOKUP(H12,Settings!$B$30:$F$36,5,0) -> ton | H12: Butane | I12: =VLOOKUP(H12,Settings!$B$30:$C$36,2,FALSE) -> 4 | J12: =VLOOKUP(H12,Settings!$B$46:$E$52,2,FALSE) -> 6 | K12: =VLOOKUP(H12,Settings!$B$46:$E$52,3,FALSE) -> 2.8e-06 | L12: =VLOOKUP(H12,Settings!$B$46:$E$52,4,FALSE) -> 5.6e-07 | M12: =F12*I12*J12 -> 57.288 | N12: =F12*I12*K12 -> 2.67344e-05 | O12: =F12*I12*L12 -> 5.34688e-06 | P12: =M12+(N12*Settings!$C$24)+(O12*Settings!$D$24) -> 57.290182 | Q12: Purchase Order
B13: Steel Making | C13: All cost centers | E13: 10203 | F13: 6.023 | G13: =VLOOKUP(H13,Settings!$B$30:$F$36,5,0) -> ton | H13: Butane | I13: =VLOOKUP(H13,Settings!$B$30:$C$36,2,FALSE) -> 4 | J13: =VLOOKUP(H13,Settings!$B$46:$E$52,2,FALSE) -> 6 | K13: =VLOOKUP(H13,Settings!$B$46:$E$52,3,FALSE) -> 2.8e-06 | L13: =VLOOKUP(H13,Settings!$B$46:$E$52,4,FALSE) -> 5.6e-07 | M13: =F13*I13*J13 -> 144.552 | N13: =F13*I13*K13 -> 6.74576e-05 | O13: =F13*I13*L13 -> 1.349152e-05 | P13: =M13+(N13*Settings!$C$24)+(O13*Settings!$D$24) -> 144.5575 | Q13: Purchase Order
B14: Hot Rolling | C14: All cost centers | E14: 10203 | F14: 2.794 | G14: =VLOOKUP(H14,Settings!$B$30:$F$36,5,0) -> ton | H14: Butane | I14: =VLOOKUP(H14,Settings!$B$30:$C$36,2,FALSE) -> 4 | J14: =VLOOKUP(H14,Settings!$B$46:$E$52,2,FALSE) -> 6 | K14: =VLOOKUP(H14,Settings!$B$46:$E$52,3,FALSE) -> 2.8e-06 | L14: =VLOOKUP(H14,Settings!$B$46:$E$52,4,FALSE) -> 5.6e-07 | M14: =F14*I14*J14 -> 67.056 | N14: =F14*I14*K14 -> 3.12928e-05 | O14: =F14*I14*L14 -> 6.25856e-06 | P14: =M14+(N14*Settings!$C$24)+(O14*Settings!$D$24) -> 67.058553 | Q14: Purchase Order
B15: Cold Rolling | C15: All cost centers | E15: 10203 | F15: 14.562 | G15: =VLOOKUP(H15,Settings!$B$30:$F$36,5,0) -> ton | H15: Butane | I15: =VLOOKUP(H15,Settings!$B$30:$C$36,2,FALSE) -> 4 | J15: =VLOOKUP(H15,Settings!$B$46:$E$52,2,FALSE) -> 6 | K15: =VLOOKUP(H15,Settings!$B$46:$E$52,3,FALSE) -> 2.8e-06 | L15: =VLOOKUP(H15,Settings!$B$46:$E$52,4,FALSE) -> 5.6e-07 | M15: =F15*I15*J15 -> 349.488 | N15: =F15*I15*K15 -> 0.0001630944 | O15: =F15*I15*L15 -> 3.261888e-05 | P15: =M15+(N15*Settings!$C$24)+(O15*Settings!$D$24) -> 349.50131 | Q15: Purchase Order
B16: Utility | C16: All cost centers | E16: 10203 | F16: 0.594 | G16: =VLOOKUP(H16,Settings!$B$30:$F$36,5,0) -> ton | H16: Butane | I16: =VLOOKUP(H16,Settings!$B$30:$C$36,2,FALSE) -> 4 | J16: =VLOOKUP(H16,Settings!$B$46:$E$52,2,FALSE) -> 6 | K16: =VLOOKUP(H16,Settings!$B$46:$E$52,3,FALSE) -> 2.8e-06 | L16: =VLOOKUP(H16,Settings!$B$46:$E$52,4,FALSE) -> 5.6e-07 | M16: =F16*I16*J16 -> 14.256 | N16: =F16*I16*K16 -> 6.6528e-06 | O16: =F16*I16*L16 -> 1.33056e-06 | P16: =M16+(N16*Settings!$C$24)+(O16*Settings!$D$24) -> 14.256543 | Q16: Purchase Order
B17: Transportation | C17: All cost centers | E17: 10203 | F17: 0.099 | G17: =VLOOKUP(H17,Settings!$B$30:$F$36,5,0) -> ton | H17: Butane | I17: =VLOOKUP(H17,Settings!$B$30:$C$36,2,FALSE) -> 4 | J17: =VLOOKUP(H17,Settings!$B$46:$E$52,2,FALSE) -> 6 | K17: =VLOOKUP(H17,Settings!$B$46:$E$52,3,FALSE) -> 2.8e-06 | L17: =VLOOKUP(H17,Settings!$B$46:$E$52,4,FALSE) -> 5.6e-07 | M17: =F17*I17*J17 -> 2.376 | N17: =F17*I17*K17 -> 1.1088e-06 | O17: =F17*I17*L17 -> 2.2176e-07 | P17: =M17+(N17*Settings!$C$24)+(O17*Settings!$D$24) -> 2.3760905 | Q17: Purchase Order
B18: Maintenance | C18: All cost centers | E18: 10203 | F18: 0.692 | G18: =VLOOKUP(H18,Settings!$B$30:$F$36,5,0) -> ton | H18: Butane | I18: =VLOOKUP(H18,Settings!$B$30:$C$36,2,FALSE) -> 4 | J18: =VLOOKUP(H18,Settings!$B$46:$E$52,2,FALSE) -> 6 | K18: =VLOOKUP(H18,Settings!$B$46:$E$52,3,FALSE) -> 2.8e-06 | L18: =VLOOKUP(H18,Settings!$B$46:$E$52,4,FALSE) -> 5.6e-07 | M18: =F18*I18*J18 -> 16.608 | N18: =F18*I18*K18 -> 7.7504e-06 | O18: =F18*I18*L18 -> 1.55008e-06 | P18: =M18+(N18*Settings!$C$24)+(O18*Settings!$D$24) -> 16.608632 | Q18: Purchase Order
B19: TAS | C19: All cost centers | E19: 10203 | F19: 4.559 | G19: =VLOOKUP(H19,Settings!$B$30:$F$36,5,0) -> ton | H19: Butane | I19: =VLOOKUP(H19,Settings!$B$30:$C$36,2,FALSE) -> 4 | J19: =VLOOKUP(H19,Settings!$B$46:$E$52,2,FALSE) -> 6 | K19: =VLOOKUP(H19,Settings!$B$46:$E$52,3,FALSE) -> 2.8e-06 | L19: =VLOOKUP(H19,Settings!$B$46:$E$52,4,FALSE) -> 5.6e-07 | M19: =F19*I19*J19 -> 109.416 | N19: =F19*I19*K19 -> 5.10608e-05 | O19: =F19*I19*L19 -> 1.021216e-05 | P19: =M19+(N19*Settings!$C$24)+(O19*Settings!$D$24) -> 109.42017 | Q19: Purchase Order
B20: Iron Making | C20: All cost centers | E20: 10350 | F20: 0 | G20: =VLOOKUP(H20,Settings!$B$30:$F$36,5,0) -> ton | H20: Acetylene | I20: =VLOOKUP(H20,Settings!$B$30:$C$36,2,FALSE) -> 5 | J20: =VLOOKUP(H20,Settings!$B$46:$E$52,2,FALSE) -> 6 | K20: =VLOOKUP(H20,Settings!$B$46:$E$52,3,FALSE) -> 0 | L20: =VLOOKUP(H20,Settings!$B$46:$E$52,4,FALSE) -> 0 | M20: =F20*I20*J20 -> 0 | N20: =F20*I20*K20 -> 0 | O20: =F20*I20*L20 -> 0 | P20: =M20+(N20*Settings!$C$24)+(O20*Settings!$D$24) -> 0 | Q20: Purchase Order
B21: Steel Making | C21: All cost centers | E21: 10350 | F21: 0 | G21: =VLOOKUP(H21,Settings!$B$30:$F$36,5,0) -> ton | H21: Acetylene | I21: =VLOOKUP(H21,Settings!$B$30:$C$36,2,FALSE) -> 5 | J21: =VLOOKUP(H21,Settings!$B$46:$E$52,2,FALSE) -> 6 | K21: =VLOOKUP(H21,Settings!$B$46:$E$52,3,FALSE) -> 0 | L21: =VLOOKUP(H21,Settings!$B$46:$E$52,4,FALSE) -> 0 | M21: =F21*I21*J21 -> 0 | N21: =F21*I21*K21 -> 0 | O21: =F21*I21*L21 -> 0 | P21: =M21+(N21*Settings!$C$24)+(O21*Settings!$D$24) -> 0 | Q21: Purchase Order
B22: Hot Rolling | C22: All cost centers | E22: 10350 | F22: 0 | G22: =VLOOKUP(H22,Settings!$B$30:$F$36,5,0) -> ton | H22: Acetylene | I22: =VLOOKUP(H22,Settings!$B$30:$C$36,2,FALSE) -> 5 | J22: =VLOOKUP(H22,Settings!$B$46:$E$52,2,FALSE) -> 6 | K22: =VLOOKUP(H22,Settings!$B$46:$E$52,3,FALSE) -> 0 | L22: =VLOOKUP(H22,Settings!$B$46:$E$52,4,FALSE) -> 0 | M22: =F22*I22*J22 -> 0 | N22: =F22*I22*K22 -> 0 | O22: =F22*I22*L22 -> 0 | P22: =M22+(N22*Settings!$C$24)+(O22*Settings!$D$24) -> 0 | Q22: Purchase Order
... B27: TAS | C27: All cost centers | E27: 10350 | F27: 0.063 | G27: =VLOOKUP(H27,Settings!$B$30:$F$36,5,0) -> ton | H27: Acetylene | I27: =VLOOKUP(H27,Settings!$B$30:$C$36,2,FALSE) -> 5 | J27: =VLOOKUP(H27,Settings!$B$46:$E$52,2,FALSE) -> 6 | K27: =VLOOKUP(H27,Settings!$B$46:$E$52,3,FALSE) -> 0 | L27: =VLOOKUP(H27,Settings!$B$46:$E$52,4,FALSE) -> 0 | M27: =F27*I27*J27 -> 1.89 | N27: =F27*I27*K27 -> 0 | O27: =F27*I27*L27 -> 0 | P27: =M27+(N27*Settings!$C$24)+(O27*Settings!$D$24) -> 1.89 | Q27: Purchase Order
B28: =VLOOKUP(D28,'Unit List'!$B$9:$E$241,4,0) -> Utility | C28: =VLOOKUP(D28,'Unit List'!$B$9:$D$241,3,0) -> Steam Production | D28: 5120 | E28: 20120 | F28: 12300000 | G28: =VLOOKUP(H28,Settings!$B$30:$F$36,5,0) -> Lit | H28: Gas oil | I28: =VLOOKUP(H28,Settings!$B$30:$C$36,2,FALSE) -> 0.01 | J28: =VLOOKUP(H28,Settings!$B$46:$E$52,2,FALSE) -> 0.0741 | K28: =VLOOKUP(H28,Settings!$B$46:$E$52,3,FALSE) -> 3e-06 | L28: =VLOOKUP(H28,Settings!$B$46:$E$52,4,FALSE) -> 6e-07 | M28: =F28*I28*J28 -> 9114.3 | N28: =F28*I28*K28 -> 0.369 | O28: =F28*I28*L28 -> 0.0738 | P28: =M28+(N28*Settings!$C$24)+(O28*Settings!$D$24) -> 9144.4104
B29: =VLOOKUP(D29,'Unit List'!$B$9:$E$241,4,0) -> Iron Making | C29: =VLOOKUP(D29,'Unit List'!$B$9:$D$241,3,0) -> Lime Making | D29: 1120 | E29: 23180 | F29: 39288.571 | G29: =VLOOKUP(H29,Settings!$B$30:$F$36,5,0) -> kNm3 | H29: Natural Gas | I29: =VLOOKUP(H29,Settings!$B$30:$C$36,2,FALSE) -> 15 | J29: =VLOOKUP(H29,Settings!$B$46:$E$52,2,FALSE) -> 0.0561 | K29: =VLOOKUP(H29,Settings!$B$46:$E$52,3,FALSE) -> 1e-06 | L29: =VLOOKUP(H29,Settings!$B$46:$E$52,4,FALSE) -> 1e-07 | M29: =F29*I29*J29 -> 33061.332 | N29: =F29*I29*K29 -> 0.58932857 | O29: =F29*I29*L29 -> 0.058932857 | P29: =M29+(N29*Settings!$C$24)+(O29*Settings!$D$24) -> 33093.333
B30: =VLOOKUP(D30,'Unit List'!$B$9:$E$241,4,0) -> Iron Making | C30: =VLOOKUP(D30,'Unit List'!$B$9:$D$241,3,0) -> Dolomite Making | D30: 1140 | E30: 23180 | F30: 17136.383 | G30: =VLOOKUP(H30,Settings!$B$30:$F$36,5,0) -> kNm3 | H30: Natural Gas | I30: =VLOOKUP(H30,Settings!$B$30:$C$36,2,FALSE) -> 15 | J30: =VLOOKUP(H30,Settings!$B$46:$E$52,2,FALSE) -> 0.0561 | K30: =VLOOKUP(H30,Settings!$B$46:$E$52,3,FALSE) -> 1e-06 | L30: =VLOOKUP(H30,Settings!$B$46:$E$52,4,FALSE) -> 1e-07 | M30: =F30*I30*J30 -> 14420.266 | N30: =F30*I30*K30 -> 0.25704574 | O30: =F30*I30*L30 -> 0.025704575 | P30: =M30+(N30*Settings!$C$24)+(O30*Settings!$D$24) -> 14434.224
